/home/jmiu/.conda/envs/new-conda/envs/pmp-new-conda/lib/python3.11/site-packages/numpy/core/getlimits.py:500: UserWarning: The value of the smallest subnormal for <class 'numpy.float64'> type is zero.
  setattr(self, word, getattr(machar, word).flat[0])
/home/jmiu/.conda/envs/new-conda/envs/pmp-new-conda/lib/python3.11/site-packages/numpy/core/getlimits.py:500: UserWarning: The value of the smallest subnormal for <class 'numpy.float64'> type is zero.
  setattr(self, word, getattr(machar, word).flat[0])
/home/jmiu/.conda/envs/new-conda/envs/pmp-new-conda/lib/python3.11/site-packages/numpy/core/getlimits.py:89: UserWarning: The value of the smallest subnormal for <class 'numpy.float64'> type is zero.
  return self._float_to_str(self.smallest_subnormal)
/home/jmiu/.conda/envs/new-conda/envs/pmp-new-conda/lib/python3.11/site-packages/numpy/core/getlimits.py:89: UserWarning: The value of the smallest subnormal for <class 'numpy.float64'> type is zero.
  return self._float_to_str(self.smallest_subnormal)
Warning: grid volume is not an integer number of pixels; cell size will be rounded to nearest pixel.
[proxy:0:0@gl3106.arc-ts.umich.edu] HYD_pmcd_pmip_control_cmd_cb (pm/pmiserv/pmip_cb.c:899): assert (!closed) failed
[proxy:0:0@gl3106.arc-ts.umich.edu] HYDT_dmxu_poll_wait_for_event (tools/demux/demux_poll.c:76): callback returned error status
[proxy:0:0@gl3106.arc-ts.umich.edu] main (pm/pmiserv/pmip.c:171): demux engine error waiting for event
srun: error: gl3107: task 1: Out Of Memory
slurmstepd: error: Detected 1 oom_kill event in StepId=874187.0. Some of the step tasks have been OOM Killed.
slurmstepd: error: Detected 1 oom_kill event in StepId=874187.0. Some of the step tasks have been OOM Killed.
Traceback (most recent call last):
  File "/home/jmiu/.conda/envs/new-conda/envs/pmp-new-conda/lib/python3.11/site-packages/pandas/io/parsers/python_parser.py", line 525, in _infer_columns
    line = self._buffered_line()
           ^^^^^^^^^^^^^^^^^^^^^
  File "/home/jmiu/.conda/envs/new-conda/envs/pmp-new-conda/lib/python3.11/site-packages/pandas/io/parsers/python_parser.py", line 620, in _buffered_line
    return self._next_line()
           ^^^^^^^^^^^^^^^^^
  File "/home/jmiu/.conda/envs/new-conda/envs/pmp-new-conda/lib/python3.11/site-packages/pandas/io/parsers/python_parser.py", line 722, in _next_line
    orig_line = self._next_iter_line(row_num=self.pos + 1)
                ^^^^^^^^^^^^^^^^^^^^^^^^^^^^^^^^^^^^^^^^^^
  File "/home/jmiu/.conda/envs/new-conda/envs/pmp-new-conda/lib/python3.11/site-packages/pandas/io/parsers/python_parser.py", line 786, in _next_iter_line
    line = next(self.data)
           ^^^^^^^^^^^^^^^
StopIteration

The above exception was the direct cause of the following exception:

Traceback (most recent call last):
  File "/home/jmiu/MEEP_Simulation/nonReciprocal_chain/flux_plot.py", line 10, in <module>
    df = pd.read_csv('output/FLUX'+name+'.dat', header=None, sep=',', engine='python')
         ^^^^^^^^^^^^^^^^^^^^^^^^^^^^^^^^^^^^^^^^^^^^^^^^^^^^^^^^^^^^^^^^^^^^^^^^^^^^^
  File "/home/jmiu/.conda/envs/new-conda/envs/pmp-new-conda/lib/python3.11/site-packages/pandas/util/_decorators.py", line 211, in wrapper
    return func(*args, **kwargs)
           ^^^^^^^^^^^^^^^^^^^^^
  File "/home/jmiu/.conda/envs/new-conda/envs/pmp-new-conda/lib/python3.11/site-packages/pandas/util/_decorators.py", line 331, in wrapper
    return func(*args, **kwargs)
           ^^^^^^^^^^^^^^^^^^^^^
  File "/home/jmiu/.conda/envs/new-conda/envs/pmp-new-conda/lib/python3.11/site-packages/pandas/io/parsers/readers.py", line 950, in read_csv
    return _read(filepath_or_buffer, kwds)
           ^^^^^^^^^^^^^^^^^^^^^^^^^^^^^^^
  File "/home/jmiu/.conda/envs/new-conda/envs/pmp-new-conda/lib/python3.11/site-packages/pandas/io/parsers/readers.py", line 605, in _read
    parser = TextFileReader(filepath_or_buffer, **kwds)
             ^^^^^^^^^^^^^^^^^^^^^^^^^^^^^^^^^^^^^^^^^^
  File "/home/jmiu/.conda/envs/new-conda/envs/pmp-new-conda/lib/python3.11/site-packages/pandas/io/parsers/readers.py", line 1442, in __init__
    self._engine = self._make_engine(f, self.engine)
                   ^^^^^^^^^^^^^^^^^^^^^^^^^^^^^^^^^
  File "/home/jmiu/.conda/envs/new-conda/envs/pmp-new-conda/lib/python3.11/site-packages/pandas/io/parsers/readers.py", line 1753, in _make_engine
    return mapping[engine](f, **self.options)
           ^^^^^^^^^^^^^^^^^^^^^^^^^^^^^^^^^^
  File "/home/jmiu/.conda/envs/new-conda/envs/pmp-new-conda/lib/python3.11/site-packages/pandas/io/parsers/python_parser.py", line 122, in __init__
    ) = self._infer_columns()
        ^^^^^^^^^^^^^^^^^^^^^
  File "/home/jmiu/.conda/envs/new-conda/envs/pmp-new-conda/lib/python3.11/site-packages/pandas/io/parsers/python_parser.py", line 529, in _infer_columns
    raise EmptyDataError("No columns to parse from file") from err
pandas.errors.EmptyDataError: No columns to parse from file
Traceback (most recent call last):
  File "/home/jmiu/.conda/envs/new-conda/envs/pmp-new-conda/lib/python3.11/site-packages/pandas/io/parsers/python_parser.py", line 525, in _infer_columns
    line = self._buffered_line()
           ^^^^^^^^^^^^^^^^^^^^^
  File "/home/jmiu/.conda/envs/new-conda/envs/pmp-new-conda/lib/python3.11/site-packages/pandas/io/parsers/python_parser.py", line 620, in _buffered_line
    return self._next_line()
           ^^^^^^^^^^^^^^^^^
  File "/home/jmiu/.conda/envs/new-conda/envs/pmp-new-conda/lib/python3.11/site-packages/pandas/io/parsers/python_parser.py", line 722, in _next_line
    orig_line = self._next_iter_line(row_num=self.pos + 1)
                ^^^^^^^^^^^^^^^^^^^^^^^^^^^^^^^^^^^^^^^^^^
  File "/home/jmiu/.conda/envs/new-conda/envs/pmp-new-conda/lib/python3.11/site-packages/pandas/io/parsers/python_parser.py", line 786, in _next_iter_line
    line = next(self.data)
           ^^^^^^^^^^^^^^^
StopIteration

The above exception was the direct cause of the following exception:

Traceback (most recent call last):
  File "/home/jmiu/MEEP_Simulation/nonReciprocal_chain/flux_plot.py", line 10, in <module>
    df = pd.read_csv('output/FLUX'+name+'.dat', header=None, sep=',', engine='python')
         ^^^^^^^^^^^^^^^^^^^^^^^^^^^^^^^^^^^^^^^^^^^^^^^^^^^^^^^^^^^^^^^^^^^^^^^^^^^^^
  File "/home/jmiu/.conda/envs/new-conda/envs/pmp-new-conda/lib/python3.11/site-packages/pandas/util/_decorators.py", line 211, in wrapper
    return func(*args, **kwargs)
           ^^^^^^^^^^^^^^^^^^^^^
  File "/home/jmiu/.conda/envs/new-conda/envs/pmp-new-conda/lib/python3.11/site-packages/pandas/util/_decorators.py", line 331, in wrapper
    return func(*args, **kwargs)
           ^^^^^^^^^^^^^^^^^^^^^
  File "/home/jmiu/.conda/envs/new-conda/envs/pmp-new-conda/lib/python3.11/site-packages/pandas/io/parsers/readers.py", line 950, in read_csv
    return _read(filepath_or_buffer, kwds)
           ^^^^^^^^^^^^^^^^^^^^^^^^^^^^^^^
  File "/home/jmiu/.conda/envs/new-conda/envs/pmp-new-conda/lib/python3.11/site-packages/pandas/io/parsers/readers.py", line 605, in _read
    parser = TextFileReader(filepath_or_buffer, **kwds)
             ^^^^^^^^^^^^^^^^^^^^^^^^^^^^^^^^^^^^^^^^^^
  File "/home/jmiu/.conda/envs/new-conda/envs/pmp-new-conda/lib/python3.11/site-packages/pandas/io/parsers/readers.py", line 1442, in __init__
    self._engine = self._make_engine(f, self.engine)
                   ^^^^^^^^^^^^^^^^^^^^^^^^^^^^^^^^^
  File "/home/jmiu/.conda/envs/new-conda/envs/pmp-new-conda/lib/python3.11/site-packages/pandas/io/parsers/readers.py", line 1753, in _make_engine
    return mapping[engine](f, **self.options)
           ^^^^^^^^^^^^^^^^^^^^^^^^^^^^^^^^^^
  File "/home/jmiu/.conda/envs/new-conda/envs/pmp-new-conda/lib/python3.11/site-packages/pandas/io/parsers/python_parser.py", line 122, in __init__
    ) = self._infer_columns()
        ^^^^^^^^^^^^^^^^^^^^^
  File "/home/jmiu/.conda/envs/new-conda/envs/pmp-new-conda/lib/python3.11/site-packages/pandas/io/parsers/python_parser.py", line 529, in _infer_columns
    raise EmptyDataError("No columns to parse from file") from err
pandas.errors.EmptyDataError: No columns to parse from file
