/home/jmiu/.conda/envs/new-conda/envs/pmp-new-conda/lib/python3.11/site-packages/numpy/core/getlimits.py:500: UserWarning: The value of the smallest subnormal for <class 'numpy.float64'> type is zero.
  setattr(self, word, getattr(machar, word).flat[0])
/home/jmiu/.conda/envs/new-conda/envs/pmp-new-conda/lib/python3.11/site-packages/numpy/core/getlimits.py:500: UserWarning: The value of the smallest subnormal for <class 'numpy.float64'> type is zero.
  setattr(self, word, getattr(machar, word).flat[0])
/home/jmiu/.conda/envs/new-conda/envs/pmp-new-conda/lib/python3.11/site-packages/numpy/core/getlimits.py:89: UserWarning: The value of the smallest subnormal for <class 'numpy.float64'> type is zero.
  return self._float_to_str(self.smallest_subnormal)
/home/jmiu/.conda/envs/new-conda/envs/pmp-new-conda/lib/python3.11/site-packages/numpy/core/getlimits.py:89: UserWarning: The value of the smallest subnormal for <class 'numpy.float64'> type is zero.
  return self._float_to_str(self.smallest_subnormal)
Warning: grid volume is not an integer number of pixels; cell size will be rounded to nearest pixel.
Warning: grid volume is not an integer number of pixels; cell size will be rounded to nearest pixel.
Traceback (most recent call last):
Traceback (most recent call last):
  File "/home/jmiu/.conda/envs/new-conda/envs/pmp-new-conda/lib/python3.11/site-packages/pandas/core/indexes/base.py", line 3803, in get_loc
  File "/home/jmiu/.conda/envs/new-conda/envs/pmp-new-conda/lib/python3.11/site-packages/pandas/core/indexes/base.py", line 3803, in get_loc
    return self._engine.get_loc(casted_key)
    return self._engine.get_loc(casted_key)
           ^^^^^^^^^^^^^^^^^^^^^^^^^^^^^^^^
  File "pandas/_libs/index.pyx", line 138, in pandas._libs.index.IndexEngine.get_loc
           ^^^^^^^^^^^^^^^^^^^^^^^^^^^^^^^^
  File "pandas/_libs/index.pyx", line 138, in pandas._libs.index.IndexEngine.get_loc
  File "pandas/_libs/index.pyx", line 165, in pandas._libs.index.IndexEngine.get_loc
  File "pandas/_libs/index.pyx", line 165, in pandas._libs.index.IndexEngine.get_loc
  File "pandas/_libs/hashtable_class_helper.pxi", line 5745, in pandas._libs.hashtable.PyObjectHashTable.get_item
  File "pandas/_libs/hashtable_class_helper.pxi", line 5745, in pandas._libs.hashtable.PyObjectHashTable.get_item
  File "pandas/_libs/hashtable_class_helper.pxi", line 5753, in pandas._libs.hashtable.PyObjectHashTable.get_item
  File "pandas/_libs/hashtable_class_helper.pxi", line 5753, in pandas._libs.hashtable.PyObjectHashTable.get_item
KeyError: ''

The above exception was the direct cause of the following exception:

Traceback (most recent call last):
  File "/home/jmiu/MEEP_Simulation/coupled_bands_asymmetric_waveguide/automated_plot_resonance.py", line 56, in <module>
KeyError: ''

The above exception was the direct cause of the following exception:

Traceback (most recent call last):
  File "/home/jmiu/MEEP_Simulation/coupled_bands_asymmetric_waveguide/automated_plot_resonance.py", line 56, in <module>
    df.loc[index, 'sep'] = parameters.loc[row_name]['Seps']
                           ~~~~~~~~~~~~~~^^^^^^^^^^
  File "/home/jmiu/.conda/envs/new-conda/envs/pmp-new-conda/lib/python3.11/site-packages/pandas/core/indexing.py", line 1073, in __getitem__
    df.loc[index, 'sep'] = parameters.loc[row_name]['Seps']
                           ~~~~~~~~~~~~~~^^^^^^^^^^
  File "/home/jmiu/.conda/envs/new-conda/envs/pmp-new-conda/lib/python3.11/site-packages/pandas/core/indexing.py", line 1073, in __getitem__
    return self._getitem_axis(maybe_callable, axis=axis)
    return self._getitem_axis(maybe_callable, axis=axis)
           ^^^^^^^^^^^^^^^^^^^^^^^^^^^^^^^^^^^^^^^^^^^^^
  File "/home/jmiu/.conda/envs/new-conda/envs/pmp-new-conda/lib/python3.11/site-packages/pandas/core/indexing.py", line 1312, in _getitem_axis
           ^^^^^^^^^^^^^^^^^^^^^^^^^^^^^^^^^^^^^^^^^^^^^
  File "/home/jmiu/.conda/envs/new-conda/envs/pmp-new-conda/lib/python3.11/site-packages/pandas/core/indexing.py", line 1312, in _getitem_axis
    return self._get_label(key, axis=axis)
           ^^^^^^^^^^^^^^^^^^^^^^^^^^^^^^^
  File "/home/jmiu/.conda/envs/new-conda/envs/pmp-new-conda/lib/python3.11/site-packages/pandas/core/indexing.py", line 1260, in _get_label
    return self._get_label(key, axis=axis)
           ^^^^^^^^^^^^^^^^^^^^^^^^^^^^^^^
  File "/home/jmiu/.conda/envs/new-conda/envs/pmp-new-conda/lib/python3.11/site-packages/pandas/core/indexing.py", line 1260, in _get_label
    return self.obj.xs(label, axis=axis)
           ^^^^^^^^^^^^^^^^^^^^^^^^^^^^^
    return self.obj.xs(label, axis=axis)
           ^^^^^^^^^^^^^^^^^^^^^^^^^^^^^
  File "/home/jmiu/.conda/envs/new-conda/envs/pmp-new-conda/lib/python3.11/site-packages/pandas/core/generic.py", line 4056, in xs
  File "/home/jmiu/.conda/envs/new-conda/envs/pmp-new-conda/lib/python3.11/site-packages/pandas/core/generic.py", line 4056, in xs
    loc = index.get_loc(key)
    loc = index.get_loc(key)
          ^^^^^^^^^^^^^^^^^^
  File "/home/jmiu/.conda/envs/new-conda/envs/pmp-new-conda/lib/python3.11/site-packages/pandas/core/indexes/base.py", line 3805, in get_loc
          ^^^^^^^^^^^^^^^^^^
  File "/home/jmiu/.conda/envs/new-conda/envs/pmp-new-conda/lib/python3.11/site-packages/pandas/core/indexes/base.py", line 3805, in get_loc
    raise KeyError(key) from err
KeyError: ''
    raise KeyError(key) from err
KeyError: ''
