Traceback (most recent call last):
  File "/home/miu/miniconda3/envs/meep/lib/python3.11/site-packages/pandas/core/indexes/base.py", line 3652, in get_loc
    return self._engine.get_loc(casted_key)
           ^^^^^^^^^^^^^^^^^^^^^^^^^^^^^^^^
  File "pandas/_libs/index.pyx", line 147, in pandas._libs.index.IndexEngine.get_loc
  File "pandas/_libs/index.pyx", line 176, in pandas._libs.index.IndexEngine.get_loc
  File "pandas/_libs/hashtable_class_helper.pxi", line 7080, in pandas._libs.hashtable.PyObjectHashTable.get_item
  File "pandas/_libs/hashtable_class_helper.pxi", line 7088, in pandas._libs.hashtable.PyObjectHashTable.get_item
KeyError: '[60,0.254,0.6,0.85,True,300,15,15,0.3175]'

The above exception was the direct cause of the following exception:

Traceback (most recent call last):
  File "/home/miu/Documents/Git/MEEP_Simulation/coupled_nanobeams_asymmetric_waveguide/nanobeam.py", line 209, in <module>
    params = params_csv.loc[args.params]
             ~~~~~~~~~~~~~~^^^^^^^^^^^^^
  File "/home/miu/miniconda3/envs/meep/lib/python3.11/site-packages/pandas/core/indexing.py", line 1103, in __getitem__
    return self._getitem_axis(maybe_callable, axis=axis)
           ^^^^^^^^^^^^^^^^^^^^^^^^^^^^^^^^^^^^^^^^^^^^^
  File "/home/miu/miniconda3/envs/meep/lib/python3.11/site-packages/pandas/core/indexing.py", line 1343, in _getitem_axis
    return self._get_label(key, axis=axis)
           ^^^^^^^^^^^^^^^^^^^^^^^^^^^^^^^
  File "/home/miu/miniconda3/envs/meep/lib/python3.11/site-packages/pandas/core/indexing.py", line 1293, in _get_label
    return self.obj.xs(label, axis=axis)
           ^^^^^^^^^^^^^^^^^^^^^^^^^^^^^
  File "/home/miu/miniconda3/envs/meep/lib/python3.11/site-packages/pandas/core/generic.py", line 4095, in xs
    loc = index.get_loc(key)
          ^^^^^^^^^^^^^^^^^^
  File "/home/miu/miniconda3/envs/meep/lib/python3.11/site-packages/pandas/core/indexes/base.py", line 3654, in get_loc
    raise KeyError(key) from err
KeyError: '[60,0.254,0.6,0.85,True,300,15,15,0.3175]'
--------------------------------------------------------------------------
Primary job  terminated normally, but 1 process returned
a non-zero exit code. Per user-direction, the job has been aborted.
--------------------------------------------------------------------------
--------------------------------------------------------------------------
mpirun detected that one or more processes exited with non-zero status, thus causing
the job to be terminated. The first process to do so was:

  Process name: [[20773,1],0]
  Exit code:    1
--------------------------------------------------------------------------
Traceback (most recent call last):
  File "/home/miu/miniconda3/envs/meep/lib/python3.11/site-packages/pandas/io/parsers/python_parser.py", line 540, in _infer_columns
    line = self._buffered_line()
           ^^^^^^^^^^^^^^^^^^^^^
  File "/home/miu/miniconda3/envs/meep/lib/python3.11/site-packages/pandas/io/parsers/python_parser.py", line 630, in _buffered_line
    return self._next_line()
           ^^^^^^^^^^^^^^^^^
  File "/home/miu/miniconda3/envs/meep/lib/python3.11/site-packages/pandas/io/parsers/python_parser.py", line 731, in _next_line
    orig_line = self._next_iter_line(row_num=self.pos + 1)
                ^^^^^^^^^^^^^^^^^^^^^^^^^^^^^^^^^^^^^^^^^^
  File "/home/miu/miniconda3/envs/meep/lib/python3.11/site-packages/pandas/io/parsers/python_parser.py", line 795, in _next_iter_line
    line = next(self.data)
           ^^^^^^^^^^^^^^^
StopIteration

The above exception was the direct cause of the following exception:

Traceback (most recent call last):
  File "/home/miu/Documents/Git/MEEP_Simulation/coupled_nanobeams_asymmetric_waveguide/flux_plot.py", line 10, in <module>
    df = pd.read_csv('output/FLUX'+name+'.dat', header=None, sep=',', engine='python')
         ^^^^^^^^^^^^^^^^^^^^^^^^^^^^^^^^^^^^^^^^^^^^^^^^^^^^^^^^^^^^^^^^^^^^^^^^^^^^^
  File "/home/miu/miniconda3/envs/meep/lib/python3.11/site-packages/pandas/io/parsers/readers.py", line 912, in read_csv
    return _read(filepath_or_buffer, kwds)
           ^^^^^^^^^^^^^^^^^^^^^^^^^^^^^^^
  File "/home/miu/miniconda3/envs/meep/lib/python3.11/site-packages/pandas/io/parsers/readers.py", line 577, in _read
    parser = TextFileReader(filepath_or_buffer, **kwds)
             ^^^^^^^^^^^^^^^^^^^^^^^^^^^^^^^^^^^^^^^^^^
  File "/home/miu/miniconda3/envs/meep/lib/python3.11/site-packages/pandas/io/parsers/readers.py", line 1407, in __init__
    self._engine = self._make_engine(f, self.engine)
                   ^^^^^^^^^^^^^^^^^^^^^^^^^^^^^^^^^
  File "/home/miu/miniconda3/envs/meep/lib/python3.11/site-packages/pandas/io/parsers/readers.py", line 1679, in _make_engine
    return mapping[engine](f, **self.options)
           ^^^^^^^^^^^^^^^^^^^^^^^^^^^^^^^^^^
  File "/home/miu/miniconda3/envs/meep/lib/python3.11/site-packages/pandas/io/parsers/python_parser.py", line 124, in __init__
    ) = self._infer_columns()
        ^^^^^^^^^^^^^^^^^^^^^
  File "/home/miu/miniconda3/envs/meep/lib/python3.11/site-packages/pandas/io/parsers/python_parser.py", line 544, in _infer_columns
    raise EmptyDataError("No columns to parse from file") from err
pandas.errors.EmptyDataError: No columns to parse from file
--------------------------------------------------------------------------
Primary job  terminated normally, but 1 process returned
a non-zero exit code. Per user-direction, the job has been aborted.
--------------------------------------------------------------------------
--------------------------------------------------------------------------
mpirun detected that one or more processes exited with non-zero status, thus causing
the job to be terminated. The first process to do so was:

  Process name: [[20785,1],0]
  Exit code:    1
--------------------------------------------------------------------------
Traceback (most recent call last):
  File "/home/miu/miniconda3/envs/meep/lib/python3.11/site-packages/pandas/core/indexes/base.py", line 3652, in get_loc
    return self._engine.get_loc(casted_key)
           ^^^^^^^^^^^^^^^^^^^^^^^^^^^^^^^^
  File "pandas/_libs/index.pyx", line 147, in pandas._libs.index.IndexEngine.get_loc
  File "pandas/_libs/index.pyx", line 176, in pandas._libs.index.IndexEngine.get_loc
  File "pandas/_libs/hashtable_class_helper.pxi", line 7080, in pandas._libs.hashtable.PyObjectHashTable.get_item
  File "pandas/_libs/hashtable_class_helper.pxi", line 7088, in pandas._libs.hashtable.PyObjectHashTable.get_item
KeyError: '[60,0.26,0.6,0.85,True,300,15,15]'

The above exception was the direct cause of the following exception:

Traceback (most recent call last):
  File "/home/miu/Documents/Git/MEEP_Simulation/coupled_nanobeams_asymmetric_waveguide/automated_plot_resonance.py", line 76, in <module>
    df.loc[index, 'sep'] = parameters.loc[row_name]['Seps']
                           ~~~~~~~~~~~~~~^^^^^^^^^^
  File "/home/miu/miniconda3/envs/meep/lib/python3.11/site-packages/pandas/core/indexing.py", line 1103, in __getitem__
    return self._getitem_axis(maybe_callable, axis=axis)
           ^^^^^^^^^^^^^^^^^^^^^^^^^^^^^^^^^^^^^^^^^^^^^
  File "/home/miu/miniconda3/envs/meep/lib/python3.11/site-packages/pandas/core/indexing.py", line 1343, in _getitem_axis
    return self._get_label(key, axis=axis)
           ^^^^^^^^^^^^^^^^^^^^^^^^^^^^^^^
  File "/home/miu/miniconda3/envs/meep/lib/python3.11/site-packages/pandas/core/indexing.py", line 1293, in _get_label
    return self.obj.xs(label, axis=axis)
           ^^^^^^^^^^^^^^^^^^^^^^^^^^^^^
  File "/home/miu/miniconda3/envs/meep/lib/python3.11/site-packages/pandas/core/generic.py", line 4095, in xs
    loc = index.get_loc(key)
          ^^^^^^^^^^^^^^^^^^
  File "/home/miu/miniconda3/envs/meep/lib/python3.11/site-packages/pandas/core/indexes/base.py", line 3654, in get_loc
    raise KeyError(key) from err
KeyError: '[60,0.26,0.6,0.85,True,300,15,15]'
--------------------------------------------------------------------------
Primary job  terminated normally, but 1 process returned
a non-zero exit code. Per user-direction, the job has been aborted.
--------------------------------------------------------------------------
--------------------------------------------------------------------------
mpirun detected that one or more processes exited with non-zero status, thus causing
the job to be terminated. The first process to do so was:

  Process name: [[20750,1],0]
  Exit code:    1
--------------------------------------------------------------------------
